{"status_code":15,"lang":"python3","run_success":false,"runtime_error":"Line 45: TypeError: [[1,1,2],[1,2,1],[2,1,1]] is not valid value for the expected return type list<list<integer>>","full_runtime_error":"TypeError: [[1,1,2],[1,2,1],[2,1,1]] is not valid value for the expected return type list<list<integer>>\n    raise TypeError(str(ret) + \" is not valid value for the expected return type list<list<integer>>\");\nLine 45 in _driver (Solution.py)\n    _driver()\nLine 52 in <module> (Solution.py)\nDuring handling of the above exception, another exception occurred:\nTypeError: '<' not supported between instances of 'int' and 'str'\nLine 14 in _serialize_int (./python3/__serializer__.py)\nLine 63 in _serialize (./python3/__serializer__.py)\nLine 48 in <listcomp> (./python3/__serializer__.py)\nLine 48 in serialize_list (./python3/__serializer__.py)\nLine 61 in _serialize (./python3/__serializer__.py)\nLine 48 in <listcomp> (./python3/__serializer__.py)\nLine 48 in serialize_list (./python3/__serializer__.py)\nLine 61 in _serialize (./python3/__serializer__.py)\n    out = ser._serialize(ret, 'list<list<integer>>')\nLine 43 in _driver (Solution.py)","status_runtime":"N/A","memory":16232000,"question_id":"47","elapsed_time":71,"compare_result":"000000000000000000000000000000000","code_output":"","std_output":"","last_testcase":"[1,1,2]","expected_output":"[[1,1,2],[1,2,1],[2,1,1]]","task_finish_time":1695429334809,"task_name":"judger.judgetask.Judge","finished":true,"total_correct":0,"total_testcases":33,"runtime_percentile":null,"status_memory":"N/A","memory_percentile":null,"pretty_lang":"Python3","submission_id":"1056713838","status_msg":"Runtime Error","state":"SUCCESS"}