{"status_code":15,"lang":"python3","run_success":false,"runtime_error":"Line 43: TypeError: [[1,2],[1,3],[1,4],[2,3],[2,4],[3,4]] is not valid value for the expected return type list<list<integer>>","full_runtime_error":"TypeError: [[1,2],[1,3],[1,4],[2,3],[2,4],[3,4]] is not valid value for the expected return type list<list<integer>>\n    raise TypeError(str(ret) + \" is not valid value for the expected return type list<list<integer>>\");\nLine 43 in _driver (Solution.py)\n    _driver()\nLine 50 in <module> (Solution.py)\nDuring handling of the above exception, another exception occurred:\nTypeError: '<' not supported between instances of 'int' and 'str'\nLine 14 in _serialize_int (./python3/__serializer__.py)\nLine 63 in _serialize (./python3/__serializer__.py)\nLine 48 in <listcomp> (./python3/__serializer__.py)\nLine 48 in serialize_list (./python3/__serializer__.py)\nLine 61 in _serialize (./python3/__serializer__.py)\nLine 48 in <listcomp> (./python3/__serializer__.py)\nLine 48 in serialize_list (./python3/__serializer__.py)\nLine 61 in _serialize (./python3/__serializer__.py)\n    out = ser._serialize(ret, 'list<list<integer>>')\nLine 41 in _driver (Solution.py)","status_runtime":"N/A","memory":16324000,"question_id":"77","elapsed_time":52,"compare_result":"000000000000000000000000000","code_output":"","std_output":"","last_testcase":"4\n2","expected_output":"[[1,2],[1,3],[1,4],[2,3],[2,4],[3,4]]","task_finish_time":1695429786200,"task_name":"judger.judgetask.Judge","finished":true,"total_correct":0,"total_testcases":27,"runtime_percentile":null,"status_memory":"N/A","memory_percentile":null,"pretty_lang":"Python3","submission_id":"1056716139","status_msg":"Runtime Error","state":"SUCCESS"}