{"status_code":15,"lang":"python3","run_success":false,"runtime_error":"Line 49: TypeError: [[1,1,6],[1,2,5],[1,7],[2,6]] is not valid value for the expected return type list<list<integer>>","full_runtime_error":"TypeError: [[1,1,6],[1,2,5],[1,7],[2,6]] is not valid value for the expected return type list<list<integer>>\n    raise TypeError(str(ret) + \" is not valid value for the expected return type list<list<integer>>\");\nLine 49 in _driver (Solution.py)\n    _driver()\nLine 56 in <module> (Solution.py)\nDuring handling of the above exception, another exception occurred:\nTypeError: '<' not supported between instances of 'int' and 'str'\nLine 14 in _serialize_int (./python3/__serializer__.py)\nLine 63 in _serialize (./python3/__serializer__.py)\nLine 48 in <listcomp> (./python3/__serializer__.py)\nLine 48 in serialize_list (./python3/__serializer__.py)\nLine 61 in _serialize (./python3/__serializer__.py)\nLine 48 in <listcomp> (./python3/__serializer__.py)\nLine 48 in serialize_list (./python3/__serializer__.py)\nLine 61 in _serialize (./python3/__serializer__.py)\n    out = ser._serialize(ret, 'list<list<integer>>')\nLine 47 in _driver (Solution.py)","status_runtime":"N/A","memory":16444000,"question_id":"40","elapsed_time":53,"compare_result":"00000000000000000000000000000000000000000000000000000000000000000000000000000000000000000000000000000000000000000000000000000000000000000000000000000000000000000000000000000000","code_output":"","std_output":"","last_testcase":"[10,1,2,7,6,1,5]\n8","expected_output":"[[1,1,6],[1,2,5],[1,7],[2,6]]","task_finish_time":1695430646440,"task_name":"judger.judgetask.Judge","finished":true,"total_correct":0,"total_testcases":176,"runtime_percentile":null,"status_memory":"N/A","memory_percentile":null,"pretty_lang":"Python3","submission_id":"1056720544","status_msg":"Runtime Error","state":"SUCCESS"}